# Обработка ошибок в асинхронном коде

Асинхронный код в JavaScript может быть подвержен ошибкам, которые нужно грамотно обрабатывать, чтобы приложение оставалось устойчивым и предсказуемым. Ошибки можно обрабатывать с помощью механизма промисов (`Promise`) или синтаксиса `async/await`. Рассмотрим основные методы обработки ошибок и их особенности.

---

## 1. Обработка ошибок в промисах

### Использование второго аргумента метода `.then()`

Метод `.then()` принимает два аргумента:
1. Функция, вызываемая при успешном выполнении промиса.
2. Функция, вызываемая при отклонении промиса (ошибке).

#### Пример:

```javascript
const fetchData = () => {
  return new Promise((resolve, reject) => {
    setTimeout(() => {
      const success = Math.random() > 0.5;
      success ? resolve("Данные успешно получены!") : reject("Ошибка получения данных.");
    }, 1000);
  });
};

fetchData().then(
  result => console.log(result), // Обработка успеха
  error => console.error(error)  // Обработка ошибки
);
```

Этот способ полезен, если вам нужно явно разделить обработку успеха и ошибок в одном вызове метода `.then()`. Однако этот подход менее удобен в цепочках промисов.

---

### Использование метода `.catch()`

Метод `.catch()` используется для обработки ошибок, возникших на любом этапе выполнения цепочки промисов. Он особенно удобен в случае сложных цепочек.

#### Пример:

```javascript
fetchData()
    .then(result => {
        console.log(result); // Обработка успеха
        return anotherAsyncOperation(); // Следующий промис
    })
    .catch(error => {
        console.error("Произошла ошибка:", error); // Обработка любой ошибки
    });
```

**Преимущества `catch`:**
- Перехватывает ошибки на любом этапе цепочки.
- Делает код более читаемым за счёт единого обработчика ошибок.

---

## 2. Обработка ошибок в `async/await`

`async/await` предоставляет более синхронный способ написания асинхронного кода, что делает его понятным и лаконичным. Для обработки ошибок в таком подходе используется блок `try/catch`.

#### Пример:

```javascript
const fetchData = async () => {
    return new Promise((resolve, reject) => {
        setTimeout(() => {
            const success = Math.random() > 0.5;
            success ? resolve("Данные успешно получены!") : reject("Ошибка получения данных.");
        }, 1000);
    });
};

const getData = async () => {
    try {
        const data = await fetchData(); // Ожидание выполнения промиса
        console.log(data); // Обработка успешного результата
    } catch (error) {
        console.error("Ошибка:", error); // Обработка ошибки
    }
};

getData();
```

### Обработка нескольких ошибок

При выполнении нескольких асинхронных операций можно обрабатывать ошибки для каждой из них отдельно или использовать общий `try/catch`.

#### Пример:

```javascript
const processAllData = async () => {
    try {
        const result1 = await fetchData();
        console.log(result1);

        const result2 = await anotherAsyncOperation(); // Здесь может произойти ошибка
        console.log(result2);
    } catch (error) {
        console.error("Ошибка во время выполнения операции:", error);
    }
};

processAllData();
```

---

## 3. Обработка ошибок в нескольких промисах

Когда нужно обработать множество асинхронных операций, есть несколько подходов:

### Метод `Promise.all`

`Promise.all` запускает все промисы параллельно, но если хотя бы один промис отклоняется, весь вызов завершится ошибкой.
#### Пример:

```javascript
const fetchAllData = async () => {
    try {
        const results = await Promise.all([fetchData(), anotherAsyncOperation()]);
        console.log("Все данные:", results);
    } catch (error) {
        console.error("Ошибка в одном из промисов:", error);
    }
};

fetchAllData();
```

### Метод `Promise.allSettled`

Для обработки успеха и ошибок каждого промиса отдельно используется `Promise.allSettled`. Этот метод возвращает массив результатов с информацией о статусе (`fulfilled` или `rejected`) для каждого промиса.

```javascript
const fetchAllData = async () => {
    const results = await Promise.allSettled([fetchData(), anotherAsyncOperation()]);

    results.forEach((result, index) => {
        if (result.status === "fulfilled") {
            console.log(`Операция ${index + 1} завершилась успешно:`, result.value);
        } else {
            console.error(`Операция ${index + 1} завершилась ошибкой:`, result.reason);
        }
    });
};

fetchAllData();
```

---

## 4. Советы по обработке ошибок

1. **Используйте `try/catch` для изоляции проблемных участков кода:**  
   Не обрабатывайте всю логику в одном общем блоке, чтобы избежать потери контекста ошибки.

2. **Используйте `Promise.allSettled` для критически важных операций:**  
   Если нужно выполнить все операции и собрать результаты, даже если некоторые из них завершатся ошибкой.

3. **Не забывайте о глобальной обработке ошибок:**  
   Используйте обработчики `window.onerror`, `window.unhandledrejection` или аналогичные механизмы для глобального мониторинга.

---

## Итог

Обработка ошибок — это ключевая часть работы с асинхронным кодом в JavaScript. Выбор метода зависит от контекста и сложности вашего приложения:
- Для простых операций используйте `.catch()`.
- В `async/await` используйте `try/catch`, чтобы поддерживать читаемость кода.
- Для параллельных операций используйте `Promise.allSettled` или обработку ошибок в `Promise.all`.

Грамотная обработка ошибок сделает ваш код устойчивым и обеспечит хорошее пользовательское впечатление.

---

## ЗАДАЧИ
Задачи по теме "Обработка ошибок в асинхронном коде"

---

### Задача 1: Обработка ошибок с использованием `.then()` и `.catch()`

У вас есть следующий код. Что выведет консоль при его выполнении?

```javascript
const fetchData = () => {
  return new Promise((resolve, reject) => {
    setTimeout(() => {
      const success = Math.random() > 0.5;
      success ? resolve("Данные успешно получены!") : reject("Ошибка получения данных.");
    }, 1000);
  });
};

fetchData()
  .then(result => console.log(result))  // Обработка успеха
  .catch(error => console.error(error)); // Обработка ошибки
```

---

### Задача 2: Перевод с `.then()` на `async/await`

Перепишите следующий код, использующий промисы с `.then()`, с использованием `async/await`.

```javascript
fetchData()
    .then(result => {
        console.log(result); // Обработка успеха
        return anotherAsyncOperation(); // Следующий промис
    })
    .catch(error => {
        console.error("Произошла ошибка:", error); // Обработка любой ошибки
    });
```

---

### Задача 3: Обработка нескольких ошибок с `async/await`

Что будет выведено на консоль, если одна из операций не удалась? Напишите код для обработки ошибок для каждой операции.

```javascript
const fetchData = async () => {
    return new Promise((resolve, reject) => {
        setTimeout(() => {
            const success = Math.random() > 0.5;
            success ? resolve("Данные успешно получены!") : reject("Ошибка получения данных.");
        }, 1000);
    });
};

const anotherAsyncOperation = async () => {
    return new Promise((resolve, reject) => {
        setTimeout(() => {
            const success = Math.random() > 0.5;
            success ? resolve("Еще одни данные!") : reject("Ошибка второй операции.");
        }, 1000);
    });
};

const processAllData = async () => {
    try {
        const result1 = await fetchData();
        console.log(result1);

        const result2 = await anotherAsyncOperation(); // Здесь может произойти ошибка
        console.log(result2);
    } catch (error) {
        console.error("Ошибка во время выполнения операции:", error);
    }
};

processAllData();
```

---

### Задача 4: Пример с `Promise.all` и `catch`

Какой результат будет, если один из промисов в `Promise.all` завершится ошибкой? Напишите код с несколькими промисами, обрабатывающими ошибку.

```javascript
const fetchAllData = async () => {
    try {
        const results = await Promise.all([fetchData(), anotherAsyncOperation()]);
        console.log("Все данные:", results);
    } catch (error) {
        console.error("Ошибка в одном из промисов:", error);
    }
};

fetchAllData();
```

---

### Задача 5: Использование `Promise.allSettled`

Предположим, что первый запрос успешен, а второй завершился с ошибкой. Что выведет этот код?

```javascript
const fetchAllData = async () => {
    const results = await Promise.allSettled([fetchData(), anotherAsyncOperation()]);

    results.forEach((result, index) => {
        if (result.status === "fulfilled") {
            console.log(`Операция ${index + 1} завершилась успешно:`, result.value);
        } else {
            console.error(`Операция ${index + 1} завершилась ошибкой:`, result.reason);
        }
    });
};

fetchAllData();
```

---

### Задача 6: Добавление глобальной обработки ошибок

Добавьте глобальный обработчик ошибок для необработанных промисов и ошибок в окне браузера с использованием `window.onerror` и `window.unhandledrejection`. Напишите пример.

---

### Задача 7: Использование `try/catch` в `async/await`

Что выведет следующий код и почему?

```javascript
const fetchData = async () => {
    return new Promise((resolve, reject) => {
        setTimeout(() => {
            const success = Math.random() > 0.5;
            success ? resolve("Данные успешно получены!") : reject("Ошибка получения данных.");
        }, 1000);
    });
};

const getData = async () => {
    try {
        const data = await fetchData(); // Ожидание выполнения промиса
        console.log(data); // Обработка успешного результата
    } catch (error) {
        console.error("Ошибка:", error); // Обработка ошибки
    }
};

getData();
```

---

### Задача 8: Обработка ошибок в нескольких промисах с `catch`

Перепишите код с `Promise.all` так, чтобы ошибки каждого промиса обрабатывались отдельно, используя `catch` для каждого промиса.

---

### Задача 9: Обработка ошибки в цепочке промисов

Что будет выведено, если один из промисов в цепочке завершится с ошибкой, а вы используете `.catch()` в конце?

```javascript
fetchData()
    .then(result => {
        console.log(result);
        return anotherAsyncOperation();
    })
    .then(result => {
        console.log(result);
    })
    .catch(error => {
        console.error("Произошла ошибка:", error);
    });
```

---

### Задача 10: Преимущества использования `try/catch` в `async/await`

Объясните, почему использование блока `try/catch` в `async/await` предпочтительнее для обработки ошибок в асинхронных операциях по сравнению с использованием `.catch()` с промисами.

---

Эти задачи помогут вам лучше понять и закрепить концепцию обработки ошибок в асинхронном коде JavaScript.

---
